Workbook

Sheet Datos
C2: Interés
A3: Tarjeta | B3: Cuotas | C3: Mi comercio | D3: Ecommerce | E3: Cetrogar | F3: On City | G3: Castillo | H3: Montes | I3: Lista Precios 4
A4: Precio | B4: 1 | C4: - | D4: - | E4: 55499 | G4: 58608 | I4: Precio
A5: VISA/MASTERCARD/AMEX | B5: 1 | C5: 0 | D5: -0.15 | E5: - | G5: - | I5: Débito/Crédito
A6: VISA/MASTER MACRO | B6: 3 | C6: 0.0665 | D6: -0.04 | E6: - | G6: 0 | I6: 3 sin int Macro
A7: VISA/MASTER MACRO | B7: 6 | C7: 0.126 | D7: 0 | E7: - | G7: 0 | I7: 6 sin int Macro
A8: VISA/MASTER MACRO | B8: 9 | C8: 0.1875 | D8: 0 | E8: - | G8: 0 | I8: 9 sin int Macro
A9: VISA/MASTER MACRO | B9: 9 | C9: 0.1875 | D9: 0.05 | E9: - | G9: - | I9: 9 con int Macro
A10: VISA/MASTER MACRO | B10: 12 | C10: 0.251 | D10: 0 | E10: - | G10: 0 | I10: 12 sin int Macro
A11: VISA/MASTER MACRO | B11: 12 | C11: 0.251 | D11: 0.1 | E11: - | G11: - | I11: 12 con int Macro
A12: VISA/MASTER MACRO | B12: 15 | C12: 0.317 | D12: 0 | E12: - | G12: - | I12: 15 sin int Macro
A13: VISA/MASTER MACRO | B13: 15 | C13: 0.317 | D13: 0.15 | E13: - | G13: 0.0195 | I13: 15 con int Macro
A14: VISA/MASTER MACRO | B14: 18 | C14: 0.385 | D14: 0 | E14: - | G14: - | I14: 18 sin int Macro
A15: VISA/MASTER MACRO | B15: 18 | C15: 0.385 | D15: 0.21 | E15: - | G15: 0.0702 | I15: 18 con int Macro
A16: VISA/MASTER NACION | B16: 3 | C16: 0.0185 | D16: -0.05 | E16: 0 | G16: 0 | I16: 3 sin int Nación 5%
A17: VISA/MASTER NACION | B17: 6 | C17: 0.0775 | D17: -0.05 | E17: 0 | G17: 0 | I17: 6 sin int Nación 5%
A18: VISA/MASTER NACION | B18: 12 | C18: 0.131 | D18: -0.05 | E18: 0 | G18: 0 | I18: 12 sin int Nación 5%
A19: VISA/MASTER NACION | B19: 12 | C19: 0.131 | D19: 0 | E19: 0 | G19: 0 | I19: 12 sin int Nación
A20: VISA/MASTER NACION | B20: 15 | C20: 0.2345 | D20: 0 | E20: 0 | G20: - | I20: 15 sin int Nación
A21: VISA/MASTER NACION | B21: 15 | C21: 0.2345 | D21: 0.09 | E21: - | G21: 0.0195 | I21: 15 con int Nación
A22: VISA/MASTER NACION | B22: 18 | C22: 0.3025 | D22: 0 | E22: - | G22: - | I22: 18 sin int Nación
A23: VISA/MASTER NACION | B23: 18 | C23: 0.3025 | D23: 0.15 | E23: 0.030598 | G23: 0.0702 | I23: 18 con int Nación
A24: VISA/MASTER NACION | B24: 20 | C24: 0.335 | D24: 0 | E24: - | G24: - | I24: 20 sin int Nación
A25: VISA/MASTER NACION | B25: 20 | C25: 0.335 | D25: 0.18 | E25: 0.089998 | G25: 0.1 | I25: 20 con int Nación
A26: NARANJAX | B26: 1 | C26: 0 | D26: -0.15 | E26: - | G26: - | I26: Débito/Crédito
A27: NARANJAX | B27: 3 | C27: 0.0295 | D27: -0.04 | E27: 0 | G27: 0 | I27: Plan Z
A28: NARANJAX | B28: 6 | C28: 0.053 | D28: 0 | E28: 0 | G28: 0 | I28: Naranja 6 s/i
A29: NARANJAX | B29: 9 | C29: 0.081 | D29: 0 | E29: 0 | G29: 0 | I29: Naranja 9 s/i
A30: NARANJAX | B30: 9 | C30: 0.081 | D30: 0.05 | E30: - | G30: - | I30: Naranja 9 c/i
A31: NARANJAX | B31: 10 | C31: 0.099 | D31: 0 | E31: - | G31: 0 | I31: Naranja 10 s/i
A32: NARANJAX | B32: 10 | C32: 0.099 | D32: 0.05 | E32: - | G32: - | I32: Naranja 10 c/i
A33: NARANJAX | B33: 12 | C33: 0.151 | D33: 0 | E33: 0 | G33: - | I33: Naranja 12 s/i
A34: NARANJAX | B34: 12 | C34: 0.151 | D34: 0.07 | E34: - | G34: 0.09 | I34: Naranja 12 c/i
A35: NARANJAX | B35: 15 | C35: 0.227 | D35: 0 | E35: - | G35: - | I35: Naranja 15 s/i
A36: NARANJAX | B36: 15 | C36: 0.227 | D36: 0.09 | E36: - | G36: - | I36: Naranja 15 c/i
A37: NARANJAX | B37: 18 | C37: 0.3195 | D37: 0 | E37: - | G37: - | I37: Naranja 18 s/i
A38: NARANJAX | B38: 18 | C38: 0.3195 | D38: 0.18 | E38: - | G38: - | I38: Naranja 18 c/i
A39: MERCADO PAGO | B39: 1 | C39: 0 | D39: -0.15 | E39: - | G39: - | I39: Débito/Crédito
A40: MERCADO PAGO | B40: 3 | C40: 0.0765 | D40: -0.04 | E40: - | G40: - | I40: 3 sin int MP
A41: MERCADO PAGO | B41: 6 | C41: 0.14 | D41: 0 | E41: - | G41: - | I41: 6 sin int MP
...

Sheet Análisis
B1: Costo | C1: CETROGAR | E1: ON CITY | G1: CASTILLO | I1: MONTES | K1: MI COMERCIO
B2: INSERTAR COSTO | D2: Markup | F2: Markup | H2: Markup | J2: Markup | L2: Markup
B3: Lista Precios 4 | C3: =Datos!E4 -> 55499 | D3: =IF(ISNUMBER($B$2),(C3/$B$2)-1,"INSERTAR COSTO") -> INSERTAR COSTO | E3: =Datos!F4 -> 0 | F3: =IF(ISNUMBER($B$2),(E3/$B$2)-1,"INSERTAR COSTO") -> INSERTAR COSTO | G3: =Datos!G4 -> 58608 | H3: =IF(ISNUMBER($B$2),(G3/$B$2)-1,"INSERTAR COSTO") -> INSERTAR COSTO | I3: =Datos!H4 -> 0 | J3: =IF(ISNUMBER($B$2),(I3/$B$2)-1,"INSERTAR COSTO") -> INSERTAR COSTO | L3: =IF(ISNUMBER($B$2),(K3/$B$2)-1,"INSERTAR COSTO") -> INSERTAR COSTO | M3: =K3*0.05 -> 0
A4: =Datos!A5 -> VISA/MASTERCARD/AMEX | B4: Débito/Crédito | C4: =IF(ISNUMBER(Datos!E5),$C$3*(1-Datos!E5)/Datos!B5,"-") -> - | D4: =IF(AND(ISNUMBER(C4),ISNUMBER($B$2)),((C4*Datos!$B5)/(1+Datos!$C5)/$B$2)-1,IF(ISNUMBER($B$2),"-","INSERTAR COSTO")) -> INSERTAR COSTO | E4: =IF(ISNUMBER(Datos!F5),$E$3*(1-Datos!F5)/Datos!B5,"-") -> - | F4: =IF(AND(ISNUMBER(E4),ISNUMBER($B$2)),((E4*Datos!$B5)/(1+Datos!$C5)/$B$2)-1,IF(ISNUMBER($B$2),"-","INSERTAR COSTO")) -> INSERTAR COSTO | G4: =IF(ISNUMBER(Datos!G5),$G$3*(1-Datos!G5)/Datos!B5,"-") -> - | H4: =IF(AND(ISNUMBER(G4),ISNUMBER($B$2)),((G4*Datos!$B5)/(1+Datos!$C5)/$B$2)-1,IF(ISNUMBER($B$2),"-","INSERTAR COSTO")) -> INSERTAR COSTO | I4: =IF(ISNUMBER(Datos!H5),$I$3*(1-Datos!H5)/Datos!B5,"-") -> - | J4: =IF(AND(ISNUMBER(I4),ISNUMBER($B$2)),((I4*Datos!$B5)/(1+Datos!$C5)/$B$2)-1,IF(ISNUMBER($B$2),"-","INSERTAR COSTO")) -> INSERTAR COSTO | K4: =$K$3*(1+Datos!D5)/Datos!B5 -> 0 | L4: =IF(ISNUMBER($B$2),((K4*Datos!$B5)/(1+Datos!$C5)/$B$2)-1,"INSERTAR COSTO") -> INSERTAR COSTO
A5: =Datos!A6 -> VISA/MASTER MACRO | B5: 3 sin int Macro | C5: =IF(ISNUMBER(Datos!E6),$C$3*(1+Datos!E6)/Datos!B6,"-") -> - | D5: =IF(AND(ISNUMBER(C5),ISNUMBER($B$2)),((C5*Datos!$B6)/(1+Datos!$C6)/$B$2)-1,IF(ISNUMBER($B$2),"-","INSERTAR COSTO")) -> INSERTAR COSTO | E5: =IF(ISNUMBER(Datos!F6),$E$3*(1+Datos!F6)/Datos!B6,"-") -> - | F5: =IF(AND(ISNUMBER(E5),ISNUMBER($B$2)),((E5*Datos!$B6)/(1+Datos!$C6)/$B$2)-1,IF(ISNUMBER($B$2),"-","INSERTAR COSTO")) -> INSERTAR COSTO | G5: =IF(ISNUMBER(Datos!G6),$G$3*(1+Datos!G6)/Datos!B6,"-") -> 19536 | H5: =IF(AND(ISNUMBER(G5),ISNUMBER($B$2)),((G5*Datos!$B6)/(1+Datos!$C6)/$B$2)-1,IF(ISNUMBER($B$2),"-","INSERTAR COSTO")) -> INSERTAR COSTO | I5: =IF(ISNUMBER(Datos!H6),$I$3*(1+Datos!H6)/Datos!B6,"-") -> - | J5: =IF(AND(ISNUMBER(I5),ISNUMBER($B$2)),((I5*Datos!$B6)/(1+Datos!$C6)/$B$2)-1,IF(ISNUMBER($B$2),"-","INSERTAR COSTO")) -> INSERTAR COSTO | K5: =$K$3*(1+Datos!D6)/Datos!B6 -> 0 | L5: =IF(ISNUMBER($B$2),((K5*Datos!$B6)/(1+Datos!$C6)/$B$2)-1,"INSERTAR COSTO") -> INSERTAR COSTO
A6: =Datos!A7 -> VISA/MASTER MACRO | B6: 6 sin int Macro | C6: =IF(ISNUMBER(Datos!E7),$C$3*(1+Datos!E7)/Datos!B7,"-") -> - | D6: =IF(AND(ISNUMBER(C6),ISNUMBER($B$2)),((C6*Datos!$B7)/(1+Datos!$C7)/$B$2)-1,IF(ISNUMBER($B$2),"-","INSERTAR COSTO")) -> INSERTAR COSTO | E6: =IF(ISNUMBER(Datos!F7),$E$3*(1+Datos!F7)/Datos!B7,"-") -> - | F6: =IF(AND(ISNUMBER(E6),ISNUMBER($B$2)),((E6*Datos!$B7)/(1+Datos!$C7)/$B$2)-1,IF(ISNUMBER($B$2),"-","INSERTAR COSTO")) -> INSERTAR COSTO | G6: =IF(ISNUMBER(Datos!G7),$G$3*(1+Datos!G7)/Datos!B7,"-") -> 9768 | H6: =IF(AND(ISNUMBER(G6),ISNUMBER($B$2)),((G6*Datos!$B7)/(1+Datos!$C7)/$B$2)-1,IF(ISNUMBER($B$2),"-","INSERTAR COSTO")) -> INSERTAR COSTO | I6: =IF(ISNUMBER(Datos!H7),$I$3*(1+Datos!H7)/Datos!B7,"-") -> - | J6: =IF(AND(ISNUMBER(I6),ISNUMBER($B$2)),((I6*Datos!$B7)/(1+Datos!$C7)/$B$2)-1,IF(ISNUMBER($B$2),"-","INSERTAR COSTO")) -> INSERTAR COSTO | K6: =$K$3*(1+Datos!D7)/Datos!B7 -> 0 | L6: =IF(ISNUMBER($B$2),((K6*Datos!$B7)/(1+Datos!$C7)/$B$2)-1,"INSERTAR COSTO") -> INSERTAR COSTO
A7: =Datos!A8 -> VISA/MASTER MACRO | B7: 9 sin int Macro | C7: =IF(ISNUMBER(Datos!E8),$C$3*(1+Datos!E8)/Datos!B8,"-") -> - | D7: =IF(AND(ISNUMBER(C7),ISNUMBER($B$2)),((C7*Datos!$B8)/(1+Datos!$C8)/$B$2)-1,IF(ISNUMBER($B$2),"-","INSERTAR COSTO")) -> INSERTAR COSTO | E7: =IF(ISNUMBER(Datos!F8),$E$3*(1+Datos!F8)/Datos!B8,"-") -> - | F7: =IF(AND(ISNUMBER(E7),ISNUMBER($B$2)),((E7*Datos!$B8)/(1+Datos!$C8)/$B$2)-1,IF(ISNUMBER($B$2),"-","INSERTAR COSTO")) -> INSERTAR COSTO | G7: =IF(ISNUMBER(Datos!G8),$G$3*(1+Datos!G8)/Datos!B8,"-") -> 6512 | H7: =IF(AND(ISNUMBER(G7),ISNUMBER($B$2)),((G7*Datos!$B8)/(1+Datos!$C8)/$B$2)-1,IF(ISNUMBER($B$2),"-","INSERTAR COSTO")) -> INSERTAR COSTO | I7: =IF(ISNUMBER(Datos!H8),$I$3*(1+Datos!H8)/Datos!B8,"-") -> - | J7: =IF(AND(ISNUMBER(I7),ISNUMBER($B$2)),((I7*Datos!$B8)/(1+Datos!$C8)/$B$2)-1,IF(ISNUMBER($B$2),"-","INSERTAR COSTO")) -> INSERTAR COSTO | K7: =$K$3*(1+Datos!D8)/Datos!B8 -> 0 | L7: =IF(ISNUMBER($B$2),((K7*Datos!$B8)/(1+Datos!$C8)/$B$2)-1,"INSERTAR COSTO") -> INSERTAR COSTO
A8: =Datos!A9 -> VISA/MASTER MACRO | B8: 9 con int Macro | C8: =IF(ISNUMBER(Datos!E9),$C$3*(1+Datos!E9)/Datos!B9,"-") -> - | D8: =IF(AND(ISNUMBER(C8),ISNUMBER($B$2)),((C8*Datos!$B9)/(1+Datos!$C9)/$B$2)-1,IF(ISNUMBER($B$2),"-","INSERTAR COSTO")) -> INSERTAR COSTO | E8: =IF(ISNUMBER(Datos!F9),$E$3*(1+Datos!F9)/Datos!B9,"-") -> - | F8: =IF(AND(ISNUMBER(E8),ISNUMBER($B$2)),((E8*Datos!$B9)/(1+Datos!$C9)/$B$2)-1,IF(ISNUMBER($B$2),"-","INSERTAR COSTO")) -> INSERTAR COSTO | G8: =IF(ISNUMBER(Datos!G9),$G$3*(1+Datos!G9)/Datos!B9,"-") -> - | H8: =IF(AND(ISNUMBER(G8),ISNUMBER($B$2)),((G8*Datos!$B9)/(1+Datos!$C9)/$B$2)-1,IF(ISNUMBER($B$2),"-","INSERTAR COSTO")) -> INSERTAR COSTO | I8: =IF(ISNUMBER(Datos!H9),$I$3*(1+Datos!H9)/Datos!B9,"-") -> - | J8: =IF(AND(ISNUMBER(I8),ISNUMBER($B$2)),((I8*Datos!$B9)/(1+Datos!$C9)/$B$2)-1,IF(ISNUMBER($B$2),"-","INSERTAR COSTO")) -> INSERTAR COSTO | K8: =$K$3*(1+Datos!D9)/Datos!B9 -> 0 | L8: =IF(ISNUMBER($B$2),((K8*Datos!$B9)/(1+Datos!$C9)/$B$2)-1,"INSERTAR COSTO") -> INSERTAR COSTO
A9: =Datos!A10 -> VISA/MASTER MACRO | B9: 12 sin int Macro | C9: =IF(ISNUMBER(Datos!E10),$C$3*(1+Datos!E10)/Datos!B10,"-") -> - | D9: =IF(AND(ISNUMBER(C9),ISNUMBER($B$2)),((C9*Datos!$B10)/(1+Datos!$C10)/$B$2)-1,IF(ISNUMBER($B$2),"-","INSERTAR COSTO")) -> INSERTAR COSTO | E9: =IF(ISNUMBER(Datos!F10),$E$3*(1+Datos!F10)/Datos!B10,"-") -> - | F9: =IF(AND(ISNUMBER(E9),ISNUMBER($B$2)),((E9*Datos!$B10)/(1+Datos!$C10)/$B$2)-1,IF(ISNUMBER($B$2),"-","INSERTAR COSTO")) -> INSERTAR COSTO | G9: =IF(ISNUMBER(Datos!G10),$G$3*(1+Datos!G10)/Datos!B10,"-") -> 4884 | H9: =IF(AND(ISNUMBER(G9),ISNUMBER($B$2)),((G9*Datos!$B10)/(1+Datos!$C10)/$B$2)-1,IF(ISNUMBER($B$2),"-","INSERTAR COSTO")) -> INSERTAR COSTO | I9: =IF(ISNUMBER(Datos!H10),$I$3*(1+Datos!H10)/Datos!B10,"-") -> - | J9: =IF(AND(ISNUMBER(I9),ISNUMBER($B$2)),((I9*Datos!$B10)/(1+Datos!$C10)/$B$2)-1,IF(ISNUMBER($B$2),"-","INSERTAR COSTO")) -> INSERTAR COSTO | K9: =$K$3*(1+Datos!D10)/Datos!B10 -> 0 | L9: =IF(ISNUMBER($B$2),((K9*Datos!$B10)/(1+Datos!$C10)/$B$2)-1,"INSERTAR COSTO") -> INSERTAR COSTO
A10: =Datos!A11 -> VISA/MASTER MACRO | B10: 12 con int Macro | C10: =IF(ISNUMBER(Datos!E11),$C$3*(1+Datos!E11)/Datos!B11,"-") -> - | D10: =IF(AND(ISNUMBER(C10),ISNUMBER($B$2)),((C10*Datos!$B11)/(1+Datos!$C11)/$B$2)-1,IF(ISNUMBER($B$2),"-","INSERTAR COSTO")) -> INSERTAR COSTO | E10: =IF(ISNUMBER(Datos!F11),$E$3*(1+Datos!F11)/Datos!B11,"-") -> - | F10: =IF(AND(ISNUMBER(E10),ISNUMBER($B$2)),((E10*Datos!$B11)/(1+Datos!$C11)/$B$2)-1,IF(ISNUMBER($B$2),"-","INSERTAR COSTO")) -> INSERTAR COSTO | G10: =IF(ISNUMBER(Datos!G11),$G$3*(1+Datos!G11)/Datos!B11,"-") -> - | H10: =IF(AND(ISNUMBER(G10),ISNUMBER($B$2)),((G10*Datos!$B11)/(1+Datos!$C11)/$B$2)-1,IF(ISNUMBER($B$2),"-","INSERTAR COSTO")) -> INSERTAR COSTO | I10: =IF(ISNUMBER(Datos!H11),$I$3*(1+Datos!H11)/Datos!B11,"-") -> - | J10: =IF(AND(ISNUMBER(I10),ISNUMBER($B$2)),((I10*Datos!$B11)/(1+Datos!$C11)/$B$2)-1,IF(ISNUMBER($B$2),"-","INSERTAR COSTO")) -> INSERTAR COSTO | K10: =$K$3*(1+Datos!D11)/Datos!B11 -> 0 | L10: =IF(ISNUMBER($B$2),((K10*Datos!$B11)/(1+Datos!$C11)/$B$2)-1,"INSERTAR COSTO") -> INSERTAR COSTO
A11: =Datos!A12 -> VISA/MASTER MACRO | B11: 15 sin int Macro | C11: =IF(ISNUMBER(Datos!E12),$C$3*(1+Datos!E12)/Datos!B12,"-") -> - | D11: =IF(AND(ISNUMBER(C11),ISNUMBER($B$2)),((C11*Datos!$B12)/(1+Datos!$C12)/$B$2)-1,IF(ISNUMBER($B$2),"-","INSERTAR COSTO")) -> INSERTAR COSTO | E11: =IF(ISNUMBER(Datos!F12),$E$3*(1+Datos!F12)/Datos!B12,"-") -> - | F11: =IF(AND(ISNUMBER(E11),ISNUMBER($B$2)),((E11*Datos!$B12)/(1+Datos!$C12)/$B$2)-1,IF(ISNUMBER($B$2),"-","INSERTAR COSTO")) -> INSERTAR COSTO | G11: =IF(ISNUMBER(Datos!G12),$G$3*(1+Datos!G12)/Datos!B12,"-") -> - | H11: =IF(AND(ISNUMBER(G11),ISNUMBER($B$2)),((G11*Datos!$B12)/(1+Datos!$C12)/$B$2)-1,IF(ISNUMBER($B$2),"-","INSERTAR COSTO")) -> INSERTAR COSTO | I11: =IF(ISNUMBER(Datos!H12),$I$3*(1+Datos!H12)/Datos!B12,"-") -> - | J11: =IF(AND(ISNUMBER(I11),ISNUMBER($B$2)),((I11*Datos!$B12)/(1+Datos!$C12)/$B$2)-1,IF(ISNUMBER($B$2),"-","INSERTAR COSTO")) -> INSERTAR COSTO | K11: =$K$3*(1+Datos!D12)/Datos!B12 -> 0 | L11: =IF(ISNUMBER($B$2),((K11*Datos!$B12)/(1+Datos!$C12)/$B$2)-1,"INSERTAR COSTO") -> INSERTAR COSTO
A12: =Datos!A13 -> VISA/MASTER MACRO | B12: 15 con int Macro | C12: =IF(ISNUMBER(Datos!E13),$C$3*(1+Datos!E13)/Datos!B13,"-") -> - | D12: =IF(AND(ISNUMBER(C12),ISNUMBER($B$2)),((C12*Datos!$B13)/(1+Datos!$C13)/$B$2)-1,IF(ISNUMBER($B$2),"-","INSERTAR COSTO")) -> INSERTAR COSTO | E12: =IF(ISNUMBER(Datos!F13),$E$3*(1+Datos!F13)/Datos!B13,"-") -> - | F12: =IF(AND(ISNUMBER(E12),ISNUMBER($B$2)),((E12*Datos!$B13)/(1+Datos!$C13)/$B$2)-1,IF(ISNUMBER($B$2),"-","INSERTAR COSTO")) -> INSERTAR COSTO | G12: =IF(ISNUMBER(Datos!G13),$G$3*(1+Datos!G13)/Datos!B13,"-") -> 3983.3904 | H12: =IF(AND(ISNUMBER(G12),ISNUMBER($B$2)),((G12*Datos!$B13)/(1+Datos!$C13)/$B$2)-1,IF(ISNUMBER($B$2),"-","INSERTAR COSTO")) -> INSERTAR COSTO | I12: =IF(ISNUMBER(Datos!H13),$I$3*(1+Datos!H13)/Datos!B13,"-") -> - | J12: =IF(AND(ISNUMBER(I12),ISNUMBER($B$2)),((I12*Datos!$B13)/(1+Datos!$C13)/$B$2)-1,IF(ISNUMBER($B$2),"-","INSERTAR COSTO")) -> INSERTAR COSTO | K12: =$K$3*(1+Datos!D13)/Datos!B13 -> 0 | L12: =IF(ISNUMBER($B$2),((K12*Datos!$B13)/(1+Datos!$C13)/$B$2)-1,"INSERTAR COSTO") -> INSERTAR COSTO
A13: =Datos!A14 -> VISA/MASTER MACRO | B13: 18 sin int Macro | C13: =IF(ISNUMBER(Datos!E14),$C$3*(1+Datos!E14)/Datos!B14,"-") -> - | D13: =IF(AND(ISNUMBER(C13),ISNUMBER($B$2)),((C13*Datos!$B14)/(1+Datos!$C14)/$B$2)-1,IF(ISNUMBER($B$2),"-","INSERTAR COSTO")) -> INSERTAR COSTO | E13: =IF(ISNUMBER(Datos!F14),$E$3*(1+Datos!F14)/Datos!B14,"-") -> - | F13: =IF(AND(ISNUMBER(E13),ISNUMBER($B$2)),((E13*Datos!$B14)/(1+Datos!$C14)/$B$2)-1,IF(ISNUMBER($B$2),"-","INSERTAR COSTO")) -> INSERTAR COSTO | G13: =IF(ISNUMBER(Datos!G14),$G$3*(1+Datos!G14)/Datos!B14,"-") -> - | H13: =IF(AND(ISNUMBER(G13),ISNUMBER($B$2)),((G13*Datos!$B14)/(1+Datos!$C14)/$B$2)-1,IF(ISNUMBER($B$2),"-","INSERTAR COSTO")) -> INSERTAR COSTO | I13: =IF(ISNUMBER(Datos!H14),$I$3*(1+Datos!H14)/Datos!B14,"-") -> - | J13: =IF(AND(ISNUMBER(I13),ISNUMBER($B$2)),((I13*Datos!$B14)/(1+Datos!$C14)/$B$2)-1,IF(ISNUMBER($B$2),"-","INSERTAR COSTO")) -> INSERTAR COSTO | K13: =$K$3*(1+Datos!D14)/Datos!B14 -> 0 | L13: =IF(ISNUMBER($B$2),((K13*Datos!$B14)/(1+Datos!$C14)/$B$2)-1,"INSERTAR COSTO") -> INSERTAR COSTO
A14: =Datos!A15 -> VISA/MASTER MACRO | B14: 18 con int Macro | C14: =IF(ISNUMBER(Datos!E15),$C$3*(1+Datos!E15)/Datos!B15,"-") -> - | D14: =IF(AND(ISNUMBER(C14),ISNUMBER($B$2)),((C14*Datos!$B15)/(1+Datos!$C15)/$B$2)-1,IF(ISNUMBER($B$2),"-","INSERTAR COSTO")) -> INSERTAR COSTO | E14: =IF(ISNUMBER(Datos!F15),$E$3*(1+Datos!F15)/Datos!B15,"-") -> - | F14: =IF(AND(ISNUMBER(E14),ISNUMBER($B$2)),((E14*Datos!$B15)/(1+Datos!$C15)/$B$2)-1,IF(ISNUMBER($B$2),"-","INSERTAR COSTO")) -> INSERTAR COSTO | G14: =IF(ISNUMBER(Datos!G15),$G$3*(1+Datos!G15)/Datos!B15,"-") -> 3484.5712 | H14: =IF(AND(ISNUMBER(G14),ISNUMBER($B$2)),((G14*Datos!$B15)/(1+Datos!$C15)/$B$2)-1,IF(ISNUMBER($B$2),"-","INSERTAR COSTO")) -> INSERTAR COSTO | I14: =IF(ISNUMBER(Datos!H15),$I$3*(1+Datos!H15)/Datos!B15,"-") -> - | J14: =IF(AND(ISNUMBER(I14),ISNUMBER($B$2)),((I14*Datos!$B15)/(1+Datos!$C15)/$B$2)-1,IF(ISNUMBER($B$2),"-","INSERTAR COSTO")) -> INSERTAR COSTO | K14: =$K$3*(1+Datos!D15)/Datos!B15 -> 0 | L14: =IF(ISNUMBER($B$2),((K14*Datos!$B15)/(1+Datos!$C15)/$B$2)-1,"INSERTAR COSTO") -> INSERTAR COSTO
A15: VISA/MASTER NACION | B15: 3 sin int Nación 5% | C15: =IF(ISNUMBER(Datos!E16),$C$3*(1+Datos!E16)/Datos!B16,"-") -> 18499.667 | D15: =IF(AND(ISNUMBER(C15),ISNUMBER($B$2)),((C15*Datos!$B16)/(1+Datos!$C16)/$B$2)-1,IF(ISNUMBER($B$2),"-","INSERTAR COSTO")) -> INSERTAR COSTO | E15: =IF(ISNUMBER(Datos!F16),$E$3*(1+Datos!F16)/Datos!B16,"-") -> - | F15: =IF(AND(ISNUMBER(E15),ISNUMBER($B$2)),((E15*Datos!$B16)/(1+Datos!$C16)/$B$2)-1,IF(ISNUMBER($B$2),"-","INSERTAR COSTO")) -> INSERTAR COSTO | G15: =IF(ISNUMBER(Datos!G16),$G$3*(1+Datos!G16)/Datos!B16,"-") -> 19536 | H15: =IF(AND(ISNUMBER(G15),ISNUMBER($B$2)),((G15*Datos!$B16)/(1+Datos!$C16)/$B$2)-1,IF(ISNUMBER($B$2),"-","INSERTAR COSTO")) -> INSERTAR COSTO | I15: =IF(ISNUMBER(Datos!H16),$I$3*(1+Datos!H16)/Datos!B16,"-") -> - | J15: =IF(AND(ISNUMBER(I15),ISNUMBER($B$2)),((I15*Datos!$B16)/(1+Datos!$C16)/$B$2)-1,IF(ISNUMBER($B$2),"-","INSERTAR COSTO")) -> INSERTAR COSTO | K15: =$K$3*(1+Datos!D16)/Datos!B16 -> 0 | L15: =IF(ISNUMBER($B$2),((K15*Datos!$B16)/(1+Datos!$C16)/$B$2)-1,"INSERTAR COSTO") -> INSERTAR COSTO
A16: VISA/MASTER NACION | B16: 6 sin int Nación 5% | C16: =IF(ISNUMBER(Datos!E17),$C$3*(1+Datos!E17)/Datos!B17,"-") -> 9249.8333 | D16: =IF(AND(ISNUMBER(C16),ISNUMBER($B$2)),((C16*Datos!$B17)/(1+Datos!$C17)/$B$2)-1,IF(ISNUMBER($B$2),"-","INSERTAR COSTO")) -> INSERTAR COSTO | E16: =IF(ISNUMBER(Datos!F17),$E$3*(1+Datos!F17)/Datos!B17,"-") -> - | F16: =IF(AND(ISNUMBER(E16),ISNUMBER($B$2)),((E16*Datos!$B17)/(1+Datos!$C17)/$B$2)-1,IF(ISNUMBER($B$2),"-","INSERTAR COSTO")) -> INSERTAR COSTO | G16: =IF(ISNUMBER(Datos!G17),$G$3*(1+Datos!G17)/Datos!B17,"-") -> 9768 | H16: =IF(AND(ISNUMBER(G16),ISNUMBER($B$2)),((G16*Datos!$B17)/(1+Datos!$C17)/$B$2)-1,IF(ISNUMBER($B$2),"-","INSERTAR COSTO")) -> INSERTAR COSTO | I16: =IF(ISNUMBER(Datos!H17),$I$3*(1+Datos!H17)/Datos!B17,"-") -> - | J16: =IF(AND(ISNUMBER(I16),ISNUMBER($B$2)),((I16*Datos!$B17)/(1+Datos!$C17)/$B$2)-1,IF(ISNUMBER($B$2),"-","INSERTAR COSTO")) -> INSERTAR COSTO | K16: =$K$3*(1+Datos!D17)/Datos!B17 -> 0 | L16: =IF(ISNUMBER($B$2),((K16*Datos!$B17)/(1+Datos!$C17)/$B$2)-1,"INSERTAR COSTO") -> INSERTAR COSTO
A17: VISA/MASTER NACION | B17: 12 sin int Nación 5% | C17: =IF(ISNUMBER(Datos!E18),$C$3*(1+Datos!E18)/Datos!B18,"-") -> 4624.9167 | D17: =IF(AND(ISNUMBER(C17),ISNUMBER($B$2)),((C17*Datos!$B18)/(1+Datos!$C18)/$B$2)-1,IF(ISNUMBER($B$2),"-","INSERTAR COSTO")) -> INSERTAR COSTO | E17: =IF(ISNUMBER(Datos!F18),$E$3*(1+Datos!F18)/Datos!B18,"-") -> - | F17: =IF(AND(ISNUMBER(E17),ISNUMBER($B$2)),((E17*Datos!$B18)/(1+Datos!$C18)/$B$2)-1,IF(ISNUMBER($B$2),"-","INSERTAR COSTO")) -> INSERTAR COSTO | G17: =IF(ISNUMBER(Datos!G18),$G$3*(1+Datos!G18)/Datos!B18,"-") -> 4884 | H17: =IF(AND(ISNUMBER(G17),ISNUMBER($B$2)),((G17*Datos!$B18)/(1+Datos!$C18)/$B$2)-1,IF(ISNUMBER($B$2),"-","INSERTAR COSTO")) -> INSERTAR COSTO | I17: =IF(ISNUMBER(Datos!H18),$I$3*(1+Datos!H18)/Datos!B18,"-") -> - | J17: =IF(AND(ISNUMBER(I17),ISNUMBER($B$2)),((I17*Datos!$B18)/(1+Datos!$C18)/$B$2)-1,IF(ISNUMBER($B$2),"-","INSERTAR COSTO")) -> INSERTAR COSTO | K17: =$K$3*(1+Datos!D18)/Datos!B18 -> 0 | L17: =IF(ISNUMBER($B$2),((K17*Datos!$B18)/(1+Datos!$C18)/$B$2)-1,"INSERTAR COSTO") -> INSERTAR COSTO
A18: VISA/MASTER NACION | B18: 12 sin int Nación | C18: =IF(ISNUMBER(Datos!E19),$C$3*(1+Datos!E19)/Datos!B19,"-") -> 4624.9167 | D18: =IF(AND(ISNUMBER(C18),ISNUMBER($B$2)),((C18*Datos!$B19)/(1+Datos!$C19)/$B$2)-1,IF(ISNUMBER($B$2),"-","INSERTAR COSTO")) -> INSERTAR COSTO | E18: =IF(ISNUMBER(Datos!F19),$E$3*(1+Datos!F19)/Datos!B19,"-") -> - | F18: =IF(AND(ISNUMBER(E18),ISNUMBER($B$2)),((E18*Datos!$B19)/(1+Datos!$C19)/$B$2)-1,IF(ISNUMBER($B$2),"-","INSERTAR COSTO")) -> INSERTAR COSTO | G18: =IF(ISNUMBER(Datos!G19),$G$3*(1+Datos!G19)/Datos!B19,"-") -> 4884 | H18: =IF(AND(ISNUMBER(G18),ISNUMBER($B$2)),((G18*Datos!$B19)/(1+Datos!$C19)/$B$2)-1,IF(ISNUMBER($B$2),"-","INSERTAR COSTO")) -> INSERTAR COSTO | I18: =IF(ISNUMBER(Datos!H19),$I$3*(1+Datos!H19)/Datos!B19,"-") -> - | J18: =IF(AND(ISNUMBER(I18),ISNUMBER($B$2)),((I18*Datos!$B19)/(1+Datos!$C19)/$B$2)-1,IF(ISNUMBER($B$2),"-","INSERTAR COSTO")) -> INSERTAR COSTO | K18: =$K$3*(1+Datos!D19)/Datos!B19 -> 0 | L18: =IF(ISNUMBER($B$2),((K18*Datos!$B19)/(1+Datos!$C19)/$B$2)-1,"INSERTAR COSTO") -> INSERTAR COSTO
A19: VISA/MASTER NACION | B19: 15 sin int Nación | C19: =IF(ISNUMBER(Datos!E20),$C$3*(1+Datos!E20)/Datos!B20,"-") -> 3699.9333 | D19: =IF(AND(ISNUMBER(C19),ISNUMBER($B$2)),((C19*Datos!$B20)/(1+Datos!$C20)/$B$2)-1,IF(ISNUMBER($B$2),"-","INSERTAR COSTO")) -> INSERTAR COSTO | E19: =IF(ISNUMBER(Datos!F20),$E$3*(1+Datos!F20)/Datos!B20,"-") -> - | F19: =IF(AND(ISNUMBER(E19),ISNUMBER($B$2)),((E19*Datos!$B20)/(1+Datos!$C20)/$B$2)-1,IF(ISNUMBER($B$2),"-","INSERTAR COSTO")) -> INSERTAR COSTO | G19: =IF(ISNUMBER(Datos!G20),$G$3*(1+Datos!G20)/Datos!B20,"-") -> - | H19: =IF(AND(ISNUMBER(G19),ISNUMBER($B$2)),((G19*Datos!$B20)/(1+Datos!$C20)/$B$2)-1,IF(ISNUMBER($B$2),"-","INSERTAR COSTO")) -> INSERTAR COSTO | I19: =IF(ISNUMBER(Datos!H20),$I$3*(1+Datos!H20)/Datos!B20,"-") -> - | J19: =IF(AND(ISNUMBER(I19),ISNUMBER($B$2)),((I19*Datos!$B20)/(1+Datos!$C20)/$B$2)-1,IF(ISNUMBER($B$2),"-","INSERTAR COSTO")) -> INSERTAR COSTO | K19: =$K$3*(1+Datos!D20)/Datos!B20 -> 0 | L19: =IF(ISNUMBER($B$2),((K19*Datos!$B20)/(1+Datos!$C20)/$B$2)-1,"INSERTAR COSTO") -> INSERTAR COSTO
A20: VISA/MASTER NACION | B20: 15 con int Nación | C20: =IF(ISNUMBER(Datos!E21),$C$3*(1+Datos!E21)/Datos!B21,"-") -> - | D20: =IF(AND(ISNUMBER(C20),ISNUMBER($B$2)),((C20*Datos!$B21)/(1+Datos!$C21)/$B$2)-1,IF(ISNUMBER($B$2),"-","INSERTAR COSTO")) -> INSERTAR COSTO | E20: =IF(ISNUMBER(Datos!F21),$E$3*(1+Datos!F21)/Datos!B21,"-") -> - | F20: =IF(AND(ISNUMBER(E20),ISNUMBER($B$2)),((E20*Datos!$B21)/(1+Datos!$C21)/$B$2)-1,IF(ISNUMBER($B$2),"-","INSERTAR COSTO")) -> INSERTAR COSTO | G20: =IF(ISNUMBER(Datos!G21),$G$3*(1+Datos!G21)/Datos!B21,"-") -> 3983.3904 | H20: =IF(AND(ISNUMBER(G20),ISNUMBER($B$2)),((G20*Datos!$B21)/(1+Datos!$C21)/$B$2)-1,IF(ISNUMBER($B$2),"-","INSERTAR COSTO")) -> INSERTAR COSTO | I20: =IF(ISNUMBER(Datos!H21),$I$3*(1+Datos!H21)/Datos!B21,"-") -> - | J20: =IF(AND(ISNUMBER(I20),ISNUMBER($B$2)),((I20*Datos!$B21)/(1+Datos!$C21)/$B$2)-1,IF(ISNUMBER($B$2),"-","INSERTAR COSTO")) -> INSERTAR COSTO | K20: =$K$3*(1+Datos!D21)/Datos!B21 -> 0 | L20: =IF(ISNUMBER($B$2),((K20*Datos!$B21)/(1+Datos!$C21)/$B$2)-1,"INSERTAR COSTO") -> INSERTAR COSTO
A21: VISA/MASTER NACION | B21: 18 sin int Nación | C21: =IF(ISNUMBER(Datos!E22),$C$3*(1+Datos!E22)/Datos!B22,"-") -> - | D21: =IF(AND(ISNUMBER(C21),ISNUMBER($B$2)),((C21*Datos!$B22)/(1+Datos!$C22)/$B$2)-1,IF(ISNUMBER($B$2),"-","INSERTAR COSTO")) -> INSERTAR COSTO | E21: =IF(ISNUMBER(Datos!F22),$E$3*(1+Datos!F22)/Datos!B22,"-") -> - | F21: =IF(AND(ISNUMBER(E21),ISNUMBER($B$2)),((E21*Datos!$B22)/(1+Datos!$C22)/$B$2)-1,IF(ISNUMBER($B$2),"-","INSERTAR COSTO")) -> INSERTAR COSTO | G21: =IF(ISNUMBER(Datos!G22),$G$3*(1+Datos!G22)/Datos!B22,"-") -> - | H21: =IF(AND(ISNUMBER(G21),ISNUMBER($B$2)),((G21*Datos!$B22)/(1+Datos!$C22)/$B$2)-1,IF(ISNUMBER($B$2),"-","INSERTAR COSTO")) -> INSERTAR COSTO | I21: =IF(ISNUMBER(Datos!H22),$I$3*(1+Datos!H22)/Datos!B22,"-") -> - | J21: =IF(AND(ISNUMBER(I21),ISNUMBER($B$2)),((I21*Datos!$B22)/(1+Datos!$C22)/$B$2)-1,IF(ISNUMBER($B$2),"-","INSERTAR COSTO")) -> INSERTAR COSTO | K21: =$K$3*(1+Datos!D22)/Datos!B22 -> 0 | L21: =IF(ISNUMBER($B$2),((K21*Datos!$B22)/(1+Datos!$C22)/$B$2)-1,"INSERTAR COSTO") -> INSERTAR COSTO
A22: VISA/MASTER NACION | B22: 18 con int Nación | C22: =IF(ISNUMBER(Datos!E23),$C$3*(1+Datos!E23)/Datos!B23,"-") -> 3177.6199 | D22: =IF(AND(ISNUMBER(C22),ISNUMBER($B$2)),((C22*Datos!$B23)/(1+Datos!$C23)/$B$2)-1,IF(ISNUMBER($B$2),"-","INSERTAR COSTO")) -> INSERTAR COSTO | E22: =IF(ISNUMBER(Datos!F23),$E$3*(1+Datos!F23)/Datos!B23,"-") -> - | F22: =IF(AND(ISNUMBER(E22),ISNUMBER($B$2)),((E22*Datos!$B23)/(1+Datos!$C23)/$B$2)-1,IF(ISNUMBER($B$2),"-","INSERTAR COSTO")) -> INSERTAR COSTO | G22: =IF(ISNUMBER(Datos!G23),$G$3*(1+Datos!G23)/Datos!B23,"-") -> 3484.5712 | H22: =IF(AND(ISNUMBER(G22),ISNUMBER($B$2)),((G22*Datos!$B23)/(1+Datos!$C23)/$B$2)-1,IF(ISNUMBER($B$2),"-","INSERTAR COSTO")) -> INSERTAR COSTO | I22: =IF(ISNUMBER(Datos!H23),$I$3*(1+Datos!H23)/Datos!B23,"-") -> - | J22: =IF(AND(ISNUMBER(I22),ISNUMBER($B$2)),((I22*Datos!$B23)/(1+Datos!$C23)/$B$2)-1,IF(ISNUMBER($B$2),"-","INSERTAR COSTO")) -> INSERTAR COSTO | K22: =$K$3*(1+Datos!D23)/Datos!B23 -> 0 | L22: =IF(ISNUMBER($B$2),((K22*Datos!$B23)/(1+Datos!$C23)/$B$2)-1,"INSERTAR COSTO") -> INSERTAR COSTO
A23: VISA/MASTER NACION | B23: 20 sin int Nación | C23: =IF(ISNUMBER(Datos!E24),$C$3*(1+Datos!E24)/Datos!B24,"-") -> - | D23: =IF(AND(ISNUMBER(C23),ISNUMBER($B$2)),((C23*Datos!$B24)/(1+Datos!$C24)/$B$2)-1,IF(ISNUMBER($B$2),"-","INSERTAR COSTO")) -> INSERTAR COSTO | E23: =IF(ISNUMBER(Datos!F24),$E$3*(1+Datos!F24)/Datos!B24,"-") -> - | F23: =IF(AND(ISNUMBER(E23),ISNUMBER($B$2)),((E23*Datos!$B24)/(1+Datos!$C24)/$B$2)-1,IF(ISNUMBER($B$2),"-","INSERTAR COSTO")) -> INSERTAR COSTO | G23: =IF(ISNUMBER(Datos!G24),$G$3*(1+Datos!G24)/Datos!B24,"-") -> - | H23: =IF(AND(ISNUMBER(G23),ISNUMBER($B$2)),((G23*Datos!$B24)/(1+Datos!$C24)/$B$2)-1,IF(ISNUMBER($B$2),"-","INSERTAR COSTO")) -> INSERTAR COSTO | I23: =IF(ISNUMBER(Datos!H24),$I$3*(1+Datos!H24)/Datos!B24,"-") -> - | J23: =IF(AND(ISNUMBER(I23),ISNUMBER($B$2)),((I23*Datos!$B24)/(1+Datos!$C24)/$B$2)-1,IF(ISNUMBER($B$2),"-","INSERTAR COSTO")) -> INSERTAR COSTO | K23: =$K$3*(1+Datos!D24)/Datos!B24 -> 0 | L23: =IF(ISNUMBER($B$2),((K23*Datos!$B24)/(1+Datos!$C24)/$B$2)-1,"INSERTAR COSTO") -> INSERTAR COSTO
A24: VISA/MASTER NACION | B24: 20 con int Nación | C24: =IF(ISNUMBER(Datos!E25),$C$3*(1+Datos!E25)/Datos!B25,"-") -> 3024.69 | D24: =IF(AND(ISNUMBER(C24),ISNUMBER($B$2)),((C24*Datos!$B25)/(1+Datos!$C25)/$B$2)-1,IF(ISNUMBER($B$2),"-","INSERTAR COSTO")) -> INSERTAR COSTO | E24: =IF(ISNUMBER(Datos!F25),$E$3*(1+Datos!F25)/Datos!B25,"-") -> - | F24: =IF(AND(ISNUMBER(E24),ISNUMBER($B$2)),((E24*Datos!$B25)/(1+Datos!$C25)/$B$2)-1,IF(ISNUMBER($B$2),"-","INSERTAR COSTO")) -> INSERTAR COSTO | G24: =IF(ISNUMBER(Datos!G25),$G$3*(1+Datos!G25)/Datos!B25,"-") -> 3223.44 | H24: =IF(AND(ISNUMBER(G24),ISNUMBER($B$2)),((G24*Datos!$B25)/(1+Datos!$C25)/$B$2)-1,IF(ISNUMBER($B$2),"-","INSERTAR COSTO")) -> INSERTAR COSTO | I24: =IF(ISNUMBER(Datos!H25),$I$3*(1+Datos!H25)/Datos!B25,"-") -> - | J24: =IF(AND(ISNUMBER(I24),ISNUMBER($B$2)),((I24*Datos!$B25)/(1+Datos!$C25)/$B$2)-1,IF(ISNUMBER($B$2),"-","INSERTAR COSTO")) -> INSERTAR COSTO | K24: =$K$3*(1+Datos!D25)/Datos!B25 -> 0 | L24: =IF(ISNUMBER($B$2),((K24*Datos!$B25)/(1+Datos!$C25)/$B$2)-1,"INSERTAR COSTO") -> INSERTAR COSTO
A25: =Datos!A26 -> NARANJAX | B25: Débito/Crédito | C25: =IF(ISNUMBER(Datos!E26),$C$3*(1+Datos!E26)/Datos!B26,"-") -> - | D25: =IF(AND(ISNUMBER(C25),ISNUMBER($B$2)),((C25*Datos!$B26)/(1+Datos!$C26)/$B$2)-1,IF(ISNUMBER($B$2),"-","INSERTAR COSTO")) -> INSERTAR COSTO | E25: =IF(ISNUMBER(Datos!F26),$E$3*(1+Datos!F26)/Datos!B26,"-") -> - | F25: =IF(AND(ISNUMBER(E25),ISNUMBER($B$2)),((E25*Datos!$B26)/(1+Datos!$C26)/$B$2)-1,IF(ISNUMBER($B$2),"-","INSERTAR COSTO")) -> INSERTAR COSTO | G25: =IF(ISNUMBER(Datos!G26),$G$3*(1+Datos!G26)/Datos!B26,"-") -> - | H25: =IF(AND(ISNUMBER(G25),ISNUMBER($B$2)),((G25*Datos!$B26)/(1+Datos!$C26)/$B$2)-1,IF(ISNUMBER($B$2),"-","INSERTAR COSTO")) -> INSERTAR COSTO | I25: =IF(ISNUMBER(Datos!H26),$I$3*(1+Datos!H26)/Datos!B26,"-") -> - | J25: =IF(AND(ISNUMBER(I25),ISNUMBER($B$2)),((I25*Datos!$B26)/(1+Datos!$C26)/$B$2)-1,IF(ISNUMBER($B$2),"-","INSERTAR COSTO")) -> INSERTAR COSTO | K25: =$K$3*(1+Datos!D26)/Datos!B26 -> 0 | L25: =IF(ISNUMBER($B$2),((K25*Datos!$B26)/(1+Datos!$C26)/$B$2)-1,"INSERTAR COSTO") -> INSERTAR COSTO
A26: =Datos!A27 -> NARANJAX | B26: Plan Z | C26: =IF(ISNUMBER(Datos!E27),$C$3*(1+Datos!E27)/Datos!B27,"-") -> 18499.667 | D26: =IF(AND(ISNUMBER(C26),ISNUMBER($B$2)),((C26*Datos!$B27)/(1+Datos!$C27)/$B$2)-1,IF(ISNUMBER($B$2),"-","INSERTAR COSTO")) -> INSERTAR COSTO | E26: =IF(ISNUMBER(Datos!F27),$E$3*(1+Datos!F27)/Datos!B27,"-") -> - | F26: =IF(AND(ISNUMBER(E26),ISNUMBER($B$2)),((E26*Datos!$B27)/(1+Datos!$C27)/$B$2)-1,IF(ISNUMBER($B$2),"-","INSERTAR COSTO")) -> INSERTAR COSTO | G26: =IF(ISNUMBER(Datos!G27),$G$3*(1+Datos!G27)/Datos!B27,"-") -> 19536 | H26: =IF(AND(ISNUMBER(G26),ISNUMBER($B$2)),((G26*Datos!$B27)/(1+Datos!$C27)/$B$2)-1,IF(ISNUMBER($B$2),"-","INSERTAR COSTO")) -> INSERTAR COSTO | I26: =IF(ISNUMBER(Datos!H27),$I$3*(1+Datos!H27)/Datos!B27,"-") -> - | J26: =IF(AND(ISNUMBER(I26),ISNUMBER($B$2)),((I26*Datos!$B27)/(1+Datos!$C27)/$B$2)-1,IF(ISNUMBER($B$2),"-","INSERTAR COSTO")) -> INSERTAR COSTO | K26: =$K$3*(1+Datos!D27)/Datos!B27 -> 0 | L26: =IF(ISNUMBER($B$2),((K26*Datos!$B27)/(1+Datos!$C27)/$B$2)-1,"INSERTAR COSTO") -> INSERTAR COSTO
A27: =Datos!A28 -> NARANJAX | B27: Naranja 6 s/i | C27: =IF(ISNUMBER(Datos!E28),$C$3*(1+Datos!E28)/Datos!B28,"-") -> 9249.8333 | D27: =IF(AND(ISNUMBER(C27),ISNUMBER($B$2)),((C27*Datos!$B28)/(1+Datos!$C28)/$B$2)-1,IF(ISNUMBER($B$2),"-","INSERTAR COSTO")) -> INSERTAR COSTO | E27: =IF(ISNUMBER(Datos!F28),$E$3*(1+Datos!F28)/Datos!B28,"-") -> - | F27: =IF(AND(ISNUMBER(E27),ISNUMBER($B$2)),((E27*Datos!$B28)/(1+Datos!$C28)/$B$2)-1,IF(ISNUMBER($B$2),"-","INSERTAR COSTO")) -> INSERTAR COSTO | G27: =IF(ISNUMBER(Datos!G28),$G$3*(1+Datos!G28)/Datos!B28,"-") -> 9768 | H27: =IF(AND(ISNUMBER(G27),ISNUMBER($B$2)),((G27*Datos!$B28)/(1+Datos!$C28)/$B$2)-1,IF(ISNUMBER($B$2),"-","INSERTAR COSTO")) -> INSERTAR COSTO | I27: =IF(ISNUMBER(Datos!H28),$I$3*(1+Datos!H28)/Datos!B28,"-") -> - | J27: =IF(AND(ISNUMBER(I27),ISNUMBER($B$2)),((I27*Datos!$B28)/(1+Datos!$C28)/$B$2)-1,IF(ISNUMBER($B$2),"-","INSERTAR COSTO")) -> INSERTAR COSTO | K27: =$K$3*(1+Datos!D28)/Datos!B28 -> 0 | L27: =IF(ISNUMBER($B$2),((K27*Datos!$B28)/(1+Datos!$C28)/$B$2)-1,"INSERTAR COSTO") -> INSERTAR COSTO
A28: =Datos!A29 -> NARANJAX | B28: Naranja 9 s/i | C28: =IF(ISNUMBER(Datos!E29),$C$3*(1+Datos!E29)/Datos!B29,"-") -> 6166.5556 | D28: =IF(AND(ISNUMBER(C28),ISNUMBER($B$2)),((C28*Datos!$B29)/(1+Datos!$C29)/$B$2)-1,IF(ISNUMBER($B$2),"-","INSERTAR COSTO")) -> INSERTAR COSTO | E28: =IF(ISNUMBER(Datos!F29),$E$3*(1+Datos!F29)/Datos!B29,"-") -> - | F28: =IF(AND(ISNUMBER(E28),ISNUMBER($B$2)),((E28*Datos!$B29)/(1+Datos!$C29)/$B$2)-1,IF(ISNUMBER($B$2),"-","INSERTAR COSTO")) -> INSERTAR COSTO | G28: =IF(ISNUMBER(Datos!G29),$G$3*(1+Datos!G29)/Datos!B29,"-") -> 6512 | H28: =IF(AND(ISNUMBER(G28),ISNUMBER($B$2)),((G28*Datos!$B29)/(1+Datos!$C29)/$B$2)-1,IF(ISNUMBER($B$2),"-","INSERTAR COSTO")) -> INSERTAR COSTO | I28: =IF(ISNUMBER(Datos!H29),$I$3*(1+Datos!H29)/Datos!B29,"-") -> - | J28: =IF(AND(ISNUMBER(I28),ISNUMBER($B$2)),((I28*Datos!$B29)/(1+Datos!$C29)/$B$2)-1,IF(ISNUMBER($B$2),"-","INSERTAR COSTO")) -> INSERTAR COSTO | K28: =$K$3*(1+Datos!D29)/Datos!B29 -> 0 | L28: =IF(ISNUMBER($B$2),((K28*Datos!$B29)/(1+Datos!$C29)/$B$2)-1,"INSERTAR COSTO") -> INSERTAR COSTO
A29: =Datos!A30 -> NARANJAX | B29: Naranja 9 c/i | C29: =IF(ISNUMBER(Datos!E30),$C$3*(1+Datos!E30)/Datos!B30,"-") -> - | D29: =IF(AND(ISNUMBER(C29),ISNUMBER($B$2)),((C29*Datos!$B30)/(1+Datos!$C30)/$B$2)-1,IF(ISNUMBER($B$2),"-","INSERTAR COSTO")) -> INSERTAR COSTO | E29: =IF(ISNUMBER(Datos!F30),$E$3*(1+Datos!F30)/Datos!B30,"-") -> - | F29: =IF(AND(ISNUMBER(E29),ISNUMBER($B$2)),((E29*Datos!$B30)/(1+Datos!$C30)/$B$2)-1,IF(ISNUMBER($B$2),"-","INSERTAR COSTO")) -> INSERTAR COSTO | G29: =IF(ISNUMBER(Datos!G30),$G$3*(1+Datos!G30)/Datos!B30,"-") -> - | H29: =IF(AND(ISNUMBER(G29),ISNUMBER($B$2)),((G29*Datos!$B30)/(1+Datos!$C30)/$B$2)-1,IF(ISNUMBER($B$2),"-","INSERTAR COSTO")) -> INSERTAR COSTO | I29: =IF(ISNUMBER(Datos!H30),$I$3*(1+Datos!H30)/Datos!B30,"-") -> - | J29: =IF(AND(ISNUMBER(I29),ISNUMBER($B$2)),((I29*Datos!$B30)/(1+Datos!$C30)/$B$2)-1,IF(ISNUMBER($B$2),"-","INSERTAR COSTO")) -> INSERTAR COSTO | K29: =$K$3*(1+Datos!D30)/Datos!B30 -> 0 | L29: =IF(ISNUMBER($B$2),((K29*Datos!$B30)/(1+Datos!$C30)/$B$2)-1,"INSERTAR COSTO") -> INSERTAR COSTO
A30: =Datos!A31 -> NARANJAX | B30: Naranja 10 s/i | C30: =IF(ISNUMBER(Datos!E31),$C$3*(1+Datos!E31)/Datos!B31,"-") -> - | D30: =IF(AND(ISNUMBER(C30),ISNUMBER($B$2)),((C30*Datos!$B31)/(1+Datos!$C31)/$B$2)-1,IF(ISNUMBER($B$2),"-","INSERTAR COSTO")) -> INSERTAR COSTO | E30: =IF(ISNUMBER(Datos!F31),$E$3*(1+Datos!F31)/Datos!B31,"-") -> - | F30: =IF(AND(ISNUMBER(E30),ISNUMBER($B$2)),((E30*Datos!$B31)/(1+Datos!$C31)/$B$2)-1,IF(ISNUMBER($B$2),"-","INSERTAR COSTO")) -> INSERTAR COSTO | G30: =IF(ISNUMBER(Datos!G31),$G$3*(1+Datos!G31)/Datos!B31,"-") -> 5860.8 | H30: =IF(AND(ISNUMBER(G30),ISNUMBER($B$2)),((G30*Datos!$B31)/(1+Datos!$C31)/$B$2)-1,IF(ISNUMBER($B$2),"-","INSERTAR COSTO")) -> INSERTAR COSTO | I30: =IF(ISNUMBER(Datos!H31),$I$3*(1+Datos!H31)/Datos!B31,"-") -> - | J30: =IF(AND(ISNUMBER(I30),ISNUMBER($B$2)),((I30*Datos!$B31)/(1+Datos!$C31)/$B$2)-1,IF(ISNUMBER($B$2),"-","INSERTAR COSTO")) -> INSERTAR COSTO | K30: =$K$3*(1+Datos!D31)/Datos!B31 -> 0 | L30: =IF(ISNUMBER($B$2),((K30*Datos!$B31)/(1+Datos!$C31)/$B$2)-1,"INSERTAR COSTO") -> INSERTAR COSTO
A31: =Datos!A32 -> NARANJAX | B31: Naranja 10 c/i | C31: =IF(ISNUMBER(Datos!E32),$C$3*(1+Datos!E32)/Datos!B32,"-") -> - | D31: =IF(AND(ISNUMBER(C31),ISNUMBER($B$2)),((C31*Datos!$B32)/(1+Datos!$C32)/$B$2)-1,IF(ISNUMBER($B$2),"-","INSERTAR COSTO")) -> INSERTAR COSTO | E31: =IF(ISNUMBER(Datos!F32),$E$3*(1+Datos!F32)/Datos!B32,"-") -> - | F31: =IF(AND(ISNUMBER(E31),ISNUMBER($B$2)),((E31*Datos!$B32)/(1+Datos!$C32)/$B$2)-1,IF(ISNUMBER($B$2),"-","INSERTAR COSTO")) -> INSERTAR COSTO | G31: =IF(ISNUMBER(Datos!G32),$G$3*(1+Datos!G32)/Datos!B32,"-") -> - | H31: =IF(AND(ISNUMBER(G31),ISNUMBER($B$2)),((G31*Datos!$B32)/(1+Datos!$C32)/$B$2)-1,IF(ISNUMBER($B$2),"-","INSERTAR COSTO")) -> INSERTAR COSTO | I31: =IF(ISNUMBER(Datos!H32),$I$3*(1+Datos!H32)/Datos!B32,"-") -> - | J31: =IF(AND(ISNUMBER(I31),ISNUMBER($B$2)),((I31*Datos!$B32)/(1+Datos!$C32)/$B$2)-1,IF(ISNUMBER($B$2),"-","INSERTAR COSTO")) -> INSERTAR COSTO | K31: =$K$3*(1+Datos!D32)/Datos!B32 -> 0 | L31: =IF(ISNUMBER($B$2),((K31*Datos!$B32)/(1+Datos!$C32)/$B$2)-1,"INSERTAR COSTO") -> INSERTAR COSTO
A32: =Datos!A33 -> NARANJAX | B32: Naranja 12 s/i | C32: =IF(ISNUMBER(Datos!E33),$C$3*(1+Datos!E33)/Datos!B33,"-") -> 4624.9167 | D32: =IF(AND(ISNUMBER(C32),ISNUMBER($B$2)),((C32*Datos!$B33)/(1+Datos!$C33)/$B$2)-1,IF(ISNUMBER($B$2),"-","INSERTAR COSTO")) -> INSERTAR COSTO | E32: =IF(ISNUMBER(Datos!F33),$E$3*(1+Datos!F33)/Datos!B33,"-") -> - | F32: =IF(AND(ISNUMBER(E32),ISNUMBER($B$2)),((E32*Datos!$B33)/(1+Datos!$C33)/$B$2)-1,IF(ISNUMBER($B$2),"-","INSERTAR COSTO")) -> INSERTAR COSTO | G32: =IF(ISNUMBER(Datos!G33),$G$3*(1+Datos!G33)/Datos!B33,"-") -> - | H32: =IF(AND(ISNUMBER(G32),ISNUMBER($B$2)),((G32*Datos!$B33)/(1+Datos!$C33)/$B$2)-1,IF(ISNUMBER($B$2),"-","INSERTAR COSTO")) -> INSERTAR COSTO | I32: =IF(ISNUMBER(Datos!H33),$I$3*(1+Datos!H33)/Datos!B33,"-") -> - | J32: =IF(AND(ISNUMBER(I32),ISNUMBER($B$2)),((I32*Datos!$B33)/(1+Datos!$C33)/$B$2)-1,IF(ISNUMBER($B$2),"-","INSERTAR COSTO")) -> INSERTAR COSTO | K32: =$K$3*(1+Datos!D33)/Datos!B33 -> 0 | L32: =IF(ISNUMBER($B$2),((K32*Datos!$B33)/(1+Datos!$C33)/$B$2)-1,"INSERTAR COSTO") -> INSERTAR COSTO
A33: =Datos!A34 -> NARANJAX | B33: Naranja 12 c/i | C33: =IF(ISNUMBER(Datos!E34),$C$3*(1+Datos!E34)/Datos!B34,"-") -> - | D33: =IF(AND(ISNUMBER(C33),ISNUMBER($B$2)),((C33*Datos!$B34)/(1+Datos!$C34)/$B$2)-1,IF(ISNUMBER($B$2),"-","INSERTAR COSTO")) -> INSERTAR COSTO | E33: =IF(ISNUMBER(Datos!F34),$E$3*(1+Datos!F34)/Datos!B34,"-") -> - | F33: =IF(AND(ISNUMBER(E33),ISNUMBER($B$2)),((E33*Datos!$B34)/(1+Datos!$C34)/$B$2)-1,IF(ISNUMBER($B$2),"-","INSERTAR COSTO")) -> INSERTAR COSTO | G33: =IF(ISNUMBER(Datos!G34),$G$3*(1+Datos!G34)/Datos!B34,"-") -> 5323.56 | H33: =IF(AND(ISNUMBER(G33),ISNUMBER($B$2)),((G33*Datos!$B34)/(1+Datos!$C34)/$B$2)-1,IF(ISNUMBER($B$2),"-","INSERTAR COSTO")) -> INSERTAR COSTO | I33: =IF(ISNUMBER(Datos!H34),$I$3*(1+Datos!H34)/Datos!B34,"-") -> - | J33: =IF(AND(ISNUMBER(I33),ISNUMBER($B$2)),((I33*Datos!$B34)/(1+Datos!$C34)/$B$2)-1,IF(ISNUMBER($B$2),"-","INSERTAR COSTO")) -> INSERTAR COSTO | K33: =$K$3*(1+Datos!D34)/Datos!B34 -> 0 | L33: =IF(ISNUMBER($B$2),((K33*Datos!$B34)/(1+Datos!$C34)/$B$2)-1,"INSERTAR COSTO") -> INSERTAR COSTO
A34: =Datos!A35 -> NARANJAX | B34: Naranja 15 s/i | C34: =IF(ISNUMBER(Datos!E35),$C$3*(1+Datos!E35)/Datos!B35,"-") -> - | D34: =IF(AND(ISNUMBER(C34),ISNUMBER($B$2)),((C34*Datos!$B35)/(1+Datos!$C35)/$B$2)-1,IF(ISNUMBER($B$2),"-","INSERTAR COSTO")) -> INSERTAR COSTO | E34: =IF(ISNUMBER(Datos!F35),$E$3*(1+Datos!F35)/Datos!B35,"-") -> - | F34: =IF(AND(ISNUMBER(E34),ISNUMBER($B$2)),((E34*Datos!$B35)/(1+Datos!$C35)/$B$2)-1,IF(ISNUMBER($B$2),"-","INSERTAR COSTO")) -> INSERTAR COSTO | G34: =IF(ISNUMBER(Datos!G35),$G$3*(1+Datos!G35)/Datos!B35,"-") -> - | H34: =IF(AND(ISNUMBER(G34),ISNUMBER($B$2)),((G34*Datos!$B35)/(1+Datos!$C35)/$B$2)-1,IF(ISNUMBER($B$2),"-","INSERTAR COSTO")) -> INSERTAR COSTO | I34: =IF(ISNUMBER(Datos!H35),$I$3*(1+Datos!H35)/Datos!B35,"-") -> - | J34: =IF(AND(ISNUMBER(I34),ISNUMBER($B$2)),((I34*Datos!$B35)/(1+Datos!$C35)/$B$2)-1,IF(ISNUMBER($B$2),"-","INSERTAR COSTO")) -> INSERTAR COSTO | K34: =$K$3*(1+Datos!D35)/Datos!B35 -> 0 | L34: =IF(ISNUMBER($B$2),((K34*Datos!$B35)/(1+Datos!$C35)/$B$2)-1,"INSERTAR COSTO") -> INSERTAR COSTO
A35: =Datos!A36 -> NARANJAX | B35: Naranja 15 c/i | C35: =IF(ISNUMBER(Datos!E36),$C$3*(1+Datos!E36)/Datos!B36,"-") -> - | D35: =IF(AND(ISNUMBER(C35),ISNUMBER($B$2)),((C35*Datos!$B36)/(1+Datos!$C36)/$B$2)-1,IF(ISNUMBER($B$2),"-","INSERTAR COSTO")) -> INSERTAR COSTO | E35: =IF(ISNUMBER(Datos!F36),$E$3*(1+Datos!F36)/Datos!B36,"-") -> - | F35: =IF(AND(ISNUMBER(E35),ISNUMBER($B$2)),((E35*Datos!$B36)/(1+Datos!$C36)/$B$2)-1,IF(ISNUMBER($B$2),"-","INSERTAR COSTO")) -> INSERTAR COSTO | G35: =IF(ISNUMBER(Datos!G36),$G$3*(1+Datos!G36)/Datos!B36,"-") -> - | H35: =IF(AND(ISNUMBER(G35),ISNUMBER($B$2)),((G35*Datos!$B36)/(1+Datos!$C36)/$B$2)-1,IF(ISNUMBER($B$2),"-","INSERTAR COSTO")) -> INSERTAR COSTO | I35: =IF(ISNUMBER(Datos!H36),$I$3*(1+Datos!H36)/Datos!B36,"-") -> - | J35: =IF(AND(ISNUMBER(I35),ISNUMBER($B$2)),((I35*Datos!$B36)/(1+Datos!$C36)/$B$2)-1,IF(ISNUMBER($B$2),"-","INSERTAR COSTO")) -> INSERTAR COSTO | K35: =$K$3*(1+Datos!D36)/Datos!B36 -> 0 | L35: =IF(ISNUMBER($B$2),((K35*Datos!$B36)/(1+Datos!$C36)/$B$2)-1,"INSERTAR COSTO") -> INSERTAR COSTO
A36: =Datos!A37 -> NARANJAX | B36: Naranja 18 s/i | C36: =IF(ISNUMBER(Datos!E37),$C$3*(1+Datos!E37)/Datos!B37,"-") -> - | D36: =IF(AND(ISNUMBER(C36),ISNUMBER($B$2)),((C36*Datos!$B37)/(1+Datos!$C37)/$B$2)-1,IF(ISNUMBER($B$2),"-","INSERTAR COSTO")) -> INSERTAR COSTO | E36: =IF(ISNUMBER(Datos!F37),$E$3*(1+Datos!F37)/Datos!B37,"-") -> - | F36: =IF(AND(ISNUMBER(E36),ISNUMBER($B$2)),((E36*Datos!$B37)/(1+Datos!$C37)/$B$2)-1,IF(ISNUMBER($B$2),"-","INSERTAR COSTO")) -> INSERTAR COSTO | G36: =IF(ISNUMBER(Datos!G37),$G$3*(1+Datos!G37)/Datos!B37,"-") -> - | H36: =IF(AND(ISNUMBER(G36),ISNUMBER($B$2)),((G36*Datos!$B37)/(1+Datos!$C37)/$B$2)-1,IF(ISNUMBER($B$2),"-","INSERTAR COSTO")) -> INSERTAR COSTO | I36: =IF(ISNUMBER(Datos!H37),$I$3*(1+Datos!H37)/Datos!B37,"-") -> - | J36: =IF(AND(ISNUMBER(I36),ISNUMBER($B$2)),((I36*Datos!$B37)/(1+Datos!$C37)/$B$2)-1,IF(ISNUMBER($B$2),"-","INSERTAR COSTO")) -> INSERTAR COSTO | K36: =$K$3*(1+Datos!D37)/Datos!B37 -> 0 | L36: =IF(ISNUMBER($B$2),((K36*Datos!$B37)/(1+Datos!$C37)/$B$2)-1,"INSERTAR COSTO") -> INSERTAR COSTO
... A42: =Datos!A43 -> MERCADO PAGO | B42: 9 con int MP | C42: =IF(ISNUMBER(Datos!E43),$C$3*(1+Datos!E43)/Datos!B43,"-") -> - | D42: =IF(AND(ISNUMBER(C42),ISNUMBER($B$2)),((C42*Datos!$B43)/(1+Datos!$C43)/$B$2)-1,IF(ISNUMBER($B$2),"-","INSERTAR COSTO")) -> INSERTAR COSTO | E42: =IF(ISNUMBER(Datos!F43),$E$3*(1+Datos!F43)/Datos!B43,"-") -> - | F42: =IF(AND(ISNUMBER(E42),ISNUMBER($B$2)),((E42*Datos!$B43)/(1+Datos!$C43)/$B$2)-1,IF(ISNUMBER($B$2),"-","INSERTAR COSTO")) -> INSERTAR COSTO | G42: =IF(ISNUMBER(Datos!G43),$G$3*(1+Datos!G43)/Datos!B43,"-") -> - | H42: =IF(AND(ISNUMBER(G42),ISNUMBER($B$2)),((G42*Datos!$B43)/(1+Datos!$C43)/$B$2)-1,IF(ISNUMBER($B$2),"-","INSERTAR COSTO")) -> INSERTAR COSTO | I42: =IF(ISNUMBER(Datos!H43),$I$3*(1+Datos!H43)/Datos!B43,"-") -> - | J42: =IF(AND(ISNUMBER(I42),ISNUMBER($B$2)),((I42*Datos!$B43)/(1+Datos!$C43)/$B$2)-1,IF(ISNUMBER($B$2),"-","INSERTAR COSTO")) -> INSERTAR COSTO | K42: =$K$3*(1+Datos!D43)/Datos!B43 -> 0 | L42: =IF(ISNUMBER($B$2),((K42*Datos!$B43)/(1+Datos!$C43)/$B$2)-1,"INSERTAR COSTO") -> INSERTAR COSTO
A43: =Datos!A45 -> MERCADO PAGO | B43: 12 sin int MP | C43: =IF(ISNUMBER(Datos!E44),$C$3*(1+Datos!E44)/Datos!B44,"-") -> - | D43: =IF(AND(ISNUMBER(C43),ISNUMBER($B$2)),((C43*Datos!$B44)/(1+Datos!$C44)/$B$2)-1,IF(ISNUMBER($B$2),"-","INSERTAR COSTO")) -> INSERTAR COSTO | E43: =IF(ISNUMBER(Datos!F44),$E$3*(1+Datos!F44)/Datos!B44,"-") -> - | F43: =IF(AND(ISNUMBER(E43),ISNUMBER($B$2)),((E43*Datos!$B44)/(1+Datos!$C44)/$B$2)-1,IF(ISNUMBER($B$2),"-","INSERTAR COSTO")) -> INSERTAR COSTO | G43: =IF(ISNUMBER(Datos!G44),$G$3*(1+Datos!G44)/Datos!B44,"-") -> - | H43: =IF(AND(ISNUMBER(G43),ISNUMBER($B$2)),((G43*Datos!$B44)/(1+Datos!$C44)/$B$2)-1,IF(ISNUMBER($B$2),"-","INSERTAR COSTO")) -> INSERTAR COSTO | I43: =IF(ISNUMBER(Datos!H44),$I$3*(1+Datos!H44)/Datos!B44,"-") -> - | J43: =IF(AND(ISNUMBER(I43),ISNUMBER($B$2)),((I43*Datos!$B44)/(1+Datos!$C44)/$B$2)-1,IF(ISNUMBER($B$2),"-","INSERTAR COSTO")) -> INSERTAR COSTO | K43: =$K$3*(1+Datos!D44)/Datos!B44 -> 0 | L43: =IF(ISNUMBER($B$2),((K43*Datos!$B44)/(1+Datos!$C44)/$B$2)-1,"INSERTAR COSTO") -> INSERTAR COSTO
A44: =Datos!A45 -> MERCADO PAGO | B44: 12 con int MP | C44: =IF(ISNUMBER(Datos!E45),$C$3*(1+Datos!E45)/Datos!B45,"-") -> - | D44: =IF(AND(ISNUMBER(C44),ISNUMBER($B$2)),((C44*Datos!$B45)/(1+Datos!$C45)/$B$2)-1,IF(ISNUMBER($B$2),"-","INSERTAR COSTO")) -> INSERTAR COSTO | E44: =IF(ISNUMBER(Datos!F45),$E$3*(1+Datos!F45)/Datos!B45,"-") -> - | F44: =IF(AND(ISNUMBER(E44),ISNUMBER($B$2)),((E44*Datos!$B45)/(1+Datos!$C45)/$B$2)-1,IF(ISNUMBER($B$2),"-","INSERTAR COSTO")) -> INSERTAR COSTO | G44: =IF(ISNUMBER(Datos!G45),$G$3*(1+Datos!G45)/Datos!B45,"-") -> - | H44: =IF(AND(ISNUMBER(G44),ISNUMBER($B$2)),((G44*Datos!$B45)/(1+Datos!$C45)/$B$2)-1,IF(ISNUMBER($B$2),"-","INSERTAR COSTO")) -> INSERTAR COSTO | I44: =IF(ISNUMBER(Datos!H45),$I$3*(1+Datos!H45)/Datos!B45,"-") -> - | J44: =IF(AND(ISNUMBER(I44),ISNUMBER($B$2)),((I44*Datos!$B45)/(1+Datos!$C45)/$B$2)-1,IF(ISNUMBER($B$2),"-","INSERTAR COSTO")) -> INSERTAR COSTO | K44: =$K$3*(1+Datos!D45)/Datos!B45 -> 0 | L44: =IF(ISNUMBER($B$2),((K44*Datos!$B45)/(1+Datos!$C45)/$B$2)-1,"INSERTAR COSTO") -> INSERTAR COSTO
A45: =Datos!A46 -> MERCADO PAGO | B45: 18 con int MP | C45: =IF(ISNUMBER(Datos!E46),$C$3*(1+Datos!E46)/Datos!B46,"-") -> - | D45: =IF(AND(ISNUMBER(C45),ISNUMBER($B$2)),((C45*Datos!$B46)/(1+Datos!$C46)/$B$2)-1,IF(ISNUMBER($B$2),"-","INSERTAR COSTO")) -> INSERTAR COSTO | E45: =IF(ISNUMBER(Datos!F46),$E$3*(1+Datos!F46)/Datos!B46,"-") -> - | F45: =IF(AND(ISNUMBER(E45),ISNUMBER($B$2)),((E45*Datos!$B46)/(1+Datos!$C46)/$B$2)-1,IF(ISNUMBER($B$2),"-","INSERTAR COSTO")) -> INSERTAR COSTO | G45: =IF(ISNUMBER(Datos!G46),$G$3*(1+Datos!G46)/Datos!B46,"-") -> - | H45: =IF(AND(ISNUMBER(G45),ISNUMBER($B$2)),((G45*Datos!$B46)/(1+Datos!$C46)/$B$2)-1,IF(ISNUMBER($B$2),"-","INSERTAR COSTO")) -> INSERTAR COSTO | I45: =IF(ISNUMBER(Datos!H46),$I$3*(1+Datos!H46)/Datos!B46,"-") -> - | J45: =IF(AND(ISNUMBER(I45),ISNUMBER($B$2)),((I45*Datos!$B46)/(1+Datos!$C46)/$B$2)-1,IF(ISNUMBER($B$2),"-","INSERTAR COSTO")) -> INSERTAR COSTO | K45: =$K$3*(1+Datos!D46)/Datos!B46 -> 0 | L45: =IF(ISNUMBER($B$2),((K45*Datos!$B46)/(1+Datos!$C46)/$B$2)-1,"INSERTAR COSTO") -> INSERTAR COSTO
...
